<?xml version="1.0" ?>
<robot name="mobile_base">
  <link name="chassis">
    <inertial>
      <mass value="20.0"/>
      <origin xyz="0 0 0" rpy="0.0 -0.0 0.0"/>
      <inertia ixx="1.8166666666666667" iyy="6.8166666666666655" izz="8.333333333333332" ixy="0.0" ixz="0.0" iyz="0.0"/>
    </inertial>
    <visual name="visual">
      <origin xyz="0 0 0" rpy="0.0 -0.0 0.0"/>
      <geometry>
        <box size="2 1 0.3"/>
      </geometry>
      <material name="">
        <color rgba="0.5607843137254902 0.7137254901960784 0.4823529411764706 1"/>
      </material>
    </visual>
    <collision name="collision">
      <origin xyz="0 0 0" rpy="0.0 -0.0 0.0"/>
      <geometry>
        <box size="2 1 0.3"/>
      </geometry>
    </collision>
  </link>
  <link name="caster_wheel">
    <inertial>
      <mass value="1.0"/>
      <origin xyz="0 0 0" rpy="0.0 -0.0 0.0"/>
      <inertia ixx="0.00625" iyy="0.00625" izz="0.00625" ixy="0.0" ixz="0.0" iyz="0.0"/>
    </inertial>
    <visual name="visual">
      <origin xyz="0 0 0" rpy="0.0 -0.0 0.0"/>
      <geometry>
        <sphere radius="0.125"/>
      </geometry>
      <material name="">
        <color rgba="0.9882352941176471 0.14901960784313725 0.2784313725490196 1"/>
      </material>
    </visual>
    <collision name="collision">
      <origin xyz="0 0 0" rpy="0.0 -0.0 0.0"/>
      <geometry>
        <sphere radius="0.125"/>
      </geometry>
    </collision>
  </link>
  <link name="left_wheel">
    <inertial>
      <mass value="1.0"/>
      <origin xyz="0 0 0" rpy="0.0 -0.0 0.0"/>
      <inertia ixx="0.004114583333333333" iyy="0.004114583333333333" izz="0.0078125" ixy="0.0" ixz="0.0" iyz="0.0"/>
    </inertial>
    <visual name="visual">
      <origin xyz="0 0 0" rpy="0.0 -0.0 0.0"/>
      <geometry>
        <cylinder radius="0.125" length="0.05"/>
      </geometry>
      <material name="">
        <color rgba="0.00784313725490196 0.10588235294117647 0.9764705882352941 1"/>
      </material>
    </visual>
    <collision name="collision">
      <origin xyz="0 0 0" rpy="0.0 -0.0 0.0"/>
      <geometry>
        <cylinder radius="0.125" length="0.05"/>
      </geometry>
    </collision>
  </link>
  <link name="right_wheel">
    <inertial>
      <mass value="1.0"/>
      <origin xyz="0 0 0" rpy="0.0 -0.0 0.0"/>
      <inertia ixx="0.004114583333333333" iyy="0.004114583333333333" izz="0.0078125" ixy="0.0" ixz="0.0" iyz="0.0"/>
    </inertial>
    <visual name="visual">
      <origin xyz="0 0 0" rpy="0.0 -0.0 0.0"/>
      <geometry>
        <cylinder radius="0.125" length="0.05"/>
      </geometry>
      <material name="">
        <color rgba="0.6274509803921569 0.21176470588235294 0.13725490196078433 1"/>
      </material>
    </visual>
    <collision name="collision">
      <origin xyz="0 0 0" rpy="0.0 -0.0 0.0"/>
      <geometry>
        <cylinder radius="0.125" length="0.05"/>
      </geometry>
    </collision>
  </link>
  <link name="imu_link">
    <inertial>
      <mass value="0.01"/>
      <origin xyz="0 0 0" rpy="0.0 -0.0 0.0"/>
      <inertia ixx="1.6666666666666667e-05" iyy="1.6666666666666667e-05" izz="1.6666666666666667e-05" ixy="0.0" ixz="0.0" iyz="0.0"/>
    </inertial>
    <visual name="visual">
      <origin xyz="0 0 0" rpy="0.0 -0.0 0.0"/>
      <geometry>
        <box size="0.1 0.1 0.1"/>
      </geometry>
    </visual>
    <collision name="collision">
      <origin xyz="0 0 0" rpy="0.0 -0.0 0.0"/>
      <geometry>
        <box size="0.1 0.1 0.1"/>
      </geometry>
    </collision>
  </link>
  <link name="contact_link">
    <inertial>
      <mass value="0.01"/>
      <origin xyz="0 0 0" rpy="0.0 -0.0 0.0"/>
      <inertia ixx="1.4583333333333333e-05" iyy="1.4583333333333333e-05" izz="1.2500000000000002e-05" ixy="0.0" ixz="0.0" iyz="0.0"/>
    </inertial>
    <visual name="visual">
      <origin xyz="0 0 0" rpy="0.0 -0.0 0.0"/>
      <geometry>
        <cylinder radius="0.05" length="0.1"/>
      </geometry>
    </visual>
    <collision name="collision">
      <origin xyz="0 0 0" rpy="0.0 -0.0 0.0"/>
      <geometry>
        <cylinder radius="0.05" length="0.1"/>
      </geometry>
    </collision>
  </link>
  <link name="camera_link">
    <inertial>
      <mass value="0.01"/>
      <origin xyz="0 0 0" rpy="0.0 -0.0 0.0"/>
      <inertia ixx="1.6666666666666667e-05" iyy="1.6666666666666667e-05" izz="1.6666666666666667e-05" ixy="0.0" ixz="0.0" iyz="0.0"/>
    </inertial>
    <visual name="visual">
      <origin xyz="0 0 0" rpy="0.0 -0.0 0.0"/>
      <geometry>
        <box size="0.1 0.1 0.1"/>
      </geometry>
    </visual>
    <collision name="collision">
      <origin xyz="0 0 0" rpy="0.0 -0.0 0.0"/>
      <geometry>
        <box size="0.1 0.1 0.1"/>
      </geometry>
    </collision>
  </link>
  <joint name="caster_wheel_joint" type="fixed">
    <parent link="chassis"/>
    <child link="caster_wheel"/>
    <limit lower="0" upper="0" effort="0" velocity="0"/>
    <origin xyz="0.8 0.0 -0.125" rpy="0.0 -0.0 0.0"/>
  </joint>
  <joint name="left_wheel_joint" type="revolute">
    <parent link="chassis"/>
    <child link="left_wheel"/>
    <limit lower="-1e+16" upper="1e+16" effort="-1.0" velocity="-1.0"/>
    <axis xyz="0 0 1"/>
    <dynamics damping="0.0" friction="0.0"/>
    <origin xyz="-0.8 0.525 -0.125" rpy="5.762794389300482e-13 1.5706999999999998 1.5706999999997604"/>
  </joint>
  <joint name="right_wheel_joint" type="revolute">
    <parent link="chassis"/>
    <child link="right_wheel"/>
    <limit lower="-1e+16" upper="1e+16" effort="-1.0" velocity="-1.0"/>
    <axis xyz="0 0 1"/>
    <dynamics damping="0.0" friction="0.0"/>
    <origin xyz="-0.8 -0.525 -0.125" rpy="5.762794389300482e-13 1.5706999999999998 1.5706999999997604"/>
  </joint>
  <joint name="imu_joint" type="fixed">
    <parent link="chassis"/>
    <child link="imu_link"/>
    <limit lower="0" upper="0" effort="0" velocity="0"/>
    <origin xyz="0.0 0.0 0.0" rpy="0.0 -0.0 0.0"/>
  </joint>
  <joint name="contact_joint" type="fixed">
    <parent link="chassis"/>
    <child link="contact_link"/>
    <limit lower="0" upper="0" effort="0" velocity="0"/>
    <origin xyz="1.0 0.0 0.0" rpy="0.0 -0.0 0.0"/>
  </joint>
  <joint name="camera_joint" type="fixed">
    <parent link="chassis"/>
    <child link="camera_link"/>
    <limit lower="0" upper="0" effort="0" velocity="0"/>
    <origin xyz="1.0 0.0 0.2" rpy="0.0 -0.0 0.0"/>
  </joint>
</robot>
